Workbook
Name SeasonalWins: 'Placement Record'!$D$2:$D$1000
Name PlayerSeasonalRecordCollection: 'Placement Record'!$2:$1000
Name Teams: 'Placement Record'!$A$2:$A$1000
Name TeamARecordSet: 'Game Record'!$A$2:$B$1000
Name SeasonalLosses: 'Placement Record'!$E$2:$E$1000
Name Placements: 'Placement Record'!$B$2:$B$1000
Name Season: 'Game Record'!$E$2:$E$1000
Name TotalLosses: 'Placement Record'!$H$2:$H$1000
Name TeamB: 'Game Record'!$C$2:$C$1000
Name Winner: 'Game Record'!$G$2:$G$1000
Name TotalWins: 'Placement Record'!$G$2:$G$1000
Name TeamBPts: 'Game Record'!$D$2:$D$1000
Name SeasonalPts.: 'Placement Record'!$F$2:$F$1000
Name Matchup: 'Game Record'!$G$2:$H$1000
Name TeamA: 'Game Record'!$A$2:$A$1000
Name Week: 'Game Record'!$F$2:$F$1000
Name TotalPts.: 'Placement Record'!$I$2:$I$1000
Name SeasonalRecords: 'Placement Record'!$2:$1000
Name Seasons: 'Placement Record'!$C$2:$C$1000
Name TeamBRecordSet: 'Game Record'!$C$2:$D$1000
Name TeamAPts: 'Game Record'!$B$2:$B$1000
Name Match: 'Game Record'!$2:$1000
Name Loser: 'Game Record'!$H$2:$H$1000

Sheet Game Record
A1: Team A | B1: Team A Pts. | C1: Team B | D1: Team B Pts. | E1: Season | F1: Week | G1: Winner | H1: Loser
A2: Luke | B2: 141.2 | C2: Kadin | D2: 153.5 | E2: 2019 | F2: 1 | G2: =IF(B2 > D2, A2, C2) -> Kadin | H2: =IF(B2 < D2, A2, C2) -> Luke
A3: Jacob | B3: 157.5 | C3: Mitch | D3: 119.65 | E3: 2019 | F3: 1 | G3: =IF(B3 > D3, A3, C3) -> Jacob | H3: =IF(B3 < D3, A3, C3) -> Mitch
A4: Ruben | B4: 114.2 | C4: Raghav | D4: 152.75 | E4: 2019 | F4: 1 | G4: =IF(B4 > D4, A4, C4) -> Raghav | H4: =IF(B4 < D4, A4, C4) -> Ruben
A5: Griffin | B5: 121.1 | C5: Connor | D5: 146 | E5: 2019 | F5: 1 | G5: =IF(B5 > D5, A5, C5) -> Connor | H5: =IF(B5 < D5, A5, C5) -> Griffin
A6: Kyle | B6: 115.65 | C6: Michael | D6: 138.5 | E6: 2019 | F6: 1 | G6: =IF(B6 > D6, A6, C6) -> Michael | H6: =IF(B6 < D6, A6, C6) -> Kyle
A7: Kadin | B7: 81.2 | C7: Connor | D7: 141.65 | E7: 2019 | F7: 2 | G7: =IF(B7 > D7, A7, C7) -> Connor | H7: =IF(B7 < D7, A7, C7) -> Kadin
A8: Griffin | B8: 121.8 | C8: Ruben | D8: 129.45 | E8: 2019 | F8: 2 | G8: =IF(B8 > D8, A8, C8) -> Ruben | H8: =IF(B8 < D8, A8, C8) -> Griffin
A9: Mitch | B9: 89.2 | C9: Kyle | D9: 143.35 | E9: 2019 | F9: 2 | G9: =IF(B9 > D9, A9, C9) -> Kyle | H9: =IF(B9 < D9, A9, C9) -> Mitch
A10: Jacob | B10: 134.5 | C10: Luke | D10: 133.55 | E10: 2019 | F10: 2 | G10: =IF(B10 > D10, A10, C10) -> Jacob | H10: =IF(B10 < D10, A10, C10) -> Luke
A11: Raghav | B11: 107.25 | C11: Michael | D11: 113 | E11: 2019 | F11: 2 | G11: =IF(B11 > D11, A11, C11) -> Michael | H11: =IF(B11 < D11, A11, C11) -> Raghav
A12: Kadin | B12: 130.7 | C12: Griffin | D12: 138.7 | E12: 2019 | F12: 3 | G12: =IF(B12 > D12, A12, C12) -> Griffin | H12: =IF(B12 < D12, A12, C12) -> Kadin
A13: Luke | B13: 184 | C13: Kyle | D13: 107.45 | E13: 2019 | F13: 3 | G13: =IF(B13 > D13, A13, C13) -> Luke | H13: =IF(B13 < D13, A13, C13) -> Kyle
... A234: Jacob | B234: 92.6 | C234: Mitch | D234: 197.85 | E234: 2021 | F234: 17 | G234: =IF(B234 > D234, A234, C234) -> Mitch | H234: =IF(B234 < D234, A234, C234) -> Jacob
G235: =IF(B235 > D235, A235, C235) | H235: =IF(B235 < D235, A235, C235)
G236: =IF(B236 > D236, A236, C236) | H236: =IF(B236 < D236, A236, C236)
G237: =IF(B237 > D237, A237, C237) | H237: =IF(B237 < D237, A237, C237)
G238: =IF(B238 > D238, A238, C238) | H238: =IF(B238 < D238, A238, C238)
G239: =IF(B239 > D239, A239, C239) | H239: =IF(B239 < D239, A239, C239)
G240: =IF(B240 > D240, A240, C240) | H240: =IF(B240 < D240, A240, C240)
G241: =IF(B241 > D241, A241, C241) | H241: =IF(B241 < D241, A241, C241)
G242: =IF(B242 > D242, A242, C242) | H242: =IF(B242 < D242, A242, C242)
G243: =IF(B243 > D243, A243, C243) | H243: =IF(B243 < D243, A243, C243)
G244: =IF(B244 > D244, A244, C244) | H244: =IF(B244 < D244, A244, C244)
G245: =IF(B245 > D245, A245, C245) | H245: =IF(B245 < D245, A245, C245)
G246: =IF(B246 > D246, A246, C246) | H246: =IF(B246 < D246, A246, C246)
... G1000: =IF(B1000 > D1000, A1000, C1000) | H1000: =IF(B1000 < D1000, A1000, C1000)

Sheet Placement Record
A1: Team | B1: Placement | C1: Season | D1: Season Wins | E1: Season Losses | F1: Seasonal Pts. | G1: Total Wins | H1: Total Losses | I1: Total Pts. | J1: Seasonal Average Pts. | K1: Total Average Pts.
A2: Griffin | B2: 1 | C2: 2019 | D2: =IF(A2 = "", "", COUNTIFS('Game Record'!G:G, A2, 'Game Record'!E:E, C2)) -> 8 | E2: =IF(A2 = "", "", COUNTIFS('Game Record'!H:H, A2, 'Game Record'!E:E, C2)) -> 8 | F2: =SUMIFS(INDIRECT("Game Record!B2:B1000"), INDIRECT("Game Record!A2:A1000"), A2, INDIRECT("Game Record!E2:E1000"), C2) + SUMIFS(INDIRECT("Game Record!D2:D1000"), INDIRECT("Game Record!C2:C1000"), A2, INDIRECT("Game Record!E2:E1000"), C2) -> 2090.8 | G2: =IF(A2 = "", "", COUNTIF('Game Record'!G:G, A2)) -> 28 | H2: =IF(A2 = "", "", COUNTIF('Game Record'!H:H, A2)) -> 20 | I2: =IFERROR(__xludf.DUMMYFUNCTION("SUM(FILTER(TeamARecordSet, INDEX(TeamARecordSet, 0, 1) = A2)) + SUM(FILTER(TeamBRecordSet, INDEX(TeamBRecordSet, 0, 1) = A2))"),6498.450000000001) -> 6498.45 | J2: =IFERROR( (SUMIFS(INDIRECT("Game Record!B2:B1000"), INDIRECT("Game Record!A2:A1000"), $A2, INDIRECT("Game Record!E2:E1000"), $C2) + SUMIFS(INDIRECT("Game Record!D2:D1000"), INDIRECT("Game Record!C2:C1000"), $A2, INDIRECT("Game Record!E2:E1000"), $C2)) / (COUNTIFS(INDIRECT("Game Record!A2:A1000"), $A2, INDIRECT("Game Record!E2:E1000"), $C2) + COUNTIFS(INDIRECT("Game Record!C2:C1000"), $A2, INDIRECT("Game Record!E2:E1000"), $C2)), 0) -> 130.675 | K2: =IFERROR(I2/(G2+H2)) -> 135.38438
A3: Jacob | B3: 2 | C3: 2019 | D3: =IF(A3 = "", "", COUNTIFS('Game Record'!G:G, A3, 'Game Record'!E:E, C3)) -> 11 | E3: =IF(A3 = "", "", COUNTIFS('Game Record'!H:H, A3, 'Game Record'!E:E, C3)) -> 4 | F3: =SUMIFS(INDIRECT("Game Record!B2:B1000"), INDIRECT("Game Record!A2:A1000"), A3, INDIRECT("Game Record!E2:E1000"), C3) + SUMIFS(INDIRECT("Game Record!D2:D1000"), INDIRECT("Game Record!C2:C1000"), A3, INDIRECT("Game Record!E2:E1000"), C3) -> 1989.45 | G3: =IF(A3 = "", "", COUNTIF('Game Record'!G:G, A3)) -> 31 | H3: =IF(A3 = "", "", COUNTIF('Game Record'!H:H, A3)) -> 15 | I3: =IFERROR(__xludf.DUMMYFUNCTION("SUM(FILTER(TeamARecordSet, INDEX(TeamARecordSet, 0, 1) = A3)) + SUM(FILTER(TeamBRecordSet, INDEX(TeamBRecordSet, 0, 1) = A3))"),5915.15) -> 5915.15 | J3: =IFERROR( (SUMIFS(INDIRECT("Game Record!B2:B1000"), INDIRECT("Game Record!A2:A1000"), $A3, INDIRECT("Game Record!E2:E1000"), $C3) + SUMIFS(INDIRECT("Game Record!D2:D1000"), INDIRECT("Game Record!C2:C1000"), $A3, INDIRECT("Game Record!E2:E1000"), $C3)) / (COUNTIFS(INDIRECT("Game Record!A2:A1000"), $A3, INDIRECT("Game Record!E2:E1000"), $C3) + COUNTIFS(INDIRECT("Game Record!C2:C1000"), $A3, INDIRECT("Game Record!E2:E1000"), $C3)), 0) -> 132.63 | K3: =IFERROR(I3/(G3+H3)) -> 128.59022
A4: Kadin | B4: 3 | C4: 2019 | D4: =IF(A4 = "", "", COUNTIFS('Game Record'!G:G, A4, 'Game Record'!E:E, C4)) -> 8 | E4: =IF(A4 = "", "", COUNTIFS('Game Record'!H:H, A4, 'Game Record'!E:E, C4)) -> 8 | F4: =SUMIFS(INDIRECT("Game Record!B2:B1000"), INDIRECT("Game Record!A2:A1000"), A4, INDIRECT("Game Record!E2:E1000"), C4) + SUMIFS(INDIRECT("Game Record!D2:D1000"), INDIRECT("Game Record!C2:C1000"), A4, INDIRECT("Game Record!E2:E1000"), C4) -> 2274.35 | G4: =IF(A4 = "", "", COUNTIF('Game Record'!G:G, A4)) -> 27 | H4: =IF(A4 = "", "", COUNTIF('Game Record'!H:H, A4)) -> 21 | I4: =IFERROR(__xludf.DUMMYFUNCTION("SUM(FILTER(TeamARecordSet, INDEX(TeamARecordSet, 0, 1) = A4)) + SUM(FILTER(TeamBRecordSet, INDEX(TeamBRecordSet, 0, 1) = A4))"),6585.0999999999985) -> 6585.1 | J4: =IFERROR( (SUMIFS(INDIRECT("Game Record!B2:B1000"), INDIRECT("Game Record!A2:A1000"), $A4, INDIRECT("Game Record!E2:E1000"), $C4) + SUMIFS(INDIRECT("Game Record!D2:D1000"), INDIRECT("Game Record!C2:C1000"), $A4, INDIRECT("Game Record!E2:E1000"), $C4)) / (COUNTIFS(INDIRECT("Game Record!A2:A1000"), $A4, INDIRECT("Game Record!E2:E1000"), $C4) + COUNTIFS(INDIRECT("Game Record!C2:C1000"), $A4, INDIRECT("Game Record!E2:E1000"), $C4)), 0) -> 142.14687 | K4: =IFERROR(I4/(G4+H4)) -> 137.18958
A5: Mitch | B5: 4 | C5: 2019 | D5: =IF(A5 = "", "", COUNTIFS('Game Record'!G:G, A5, 'Game Record'!E:E, C5)) -> 8 | E5: =IF(A5 = "", "", COUNTIFS('Game Record'!H:H, A5, 'Game Record'!E:E, C5)) -> 7 | F5: =SUMIFS(INDIRECT("Game Record!B2:B1000"), INDIRECT("Game Record!A2:A1000"), A5, INDIRECT("Game Record!E2:E1000"), C5) + SUMIFS(INDIRECT("Game Record!D2:D1000"), INDIRECT("Game Record!C2:C1000"), A5, INDIRECT("Game Record!E2:E1000"), C5) -> 1808.5 | G5: =IF(A5 = "", "", COUNTIF('Game Record'!G:G, A5)) -> 22 | H5: =IF(A5 = "", "", COUNTIF('Game Record'!H:H, A5)) -> 24 | I5: =IFERROR(__xludf.DUMMYFUNCTION("SUM(FILTER(TeamARecordSet, INDEX(TeamARecordSet, 0, 1) = A5)) + SUM(FILTER(TeamBRecordSet, INDEX(TeamBRecordSet, 0, 1) = A5))"),5774.249999999999) -> 5774.25 | J5: =IFERROR( (SUMIFS(INDIRECT("Game Record!B2:B1000"), INDIRECT("Game Record!A2:A1000"), $A5, INDIRECT("Game Record!E2:E1000"), $C5) + SUMIFS(INDIRECT("Game Record!D2:D1000"), INDIRECT("Game Record!C2:C1000"), $A5, INDIRECT("Game Record!E2:E1000"), $C5)) / (COUNTIFS(INDIRECT("Game Record!A2:A1000"), $A5, INDIRECT("Game Record!E2:E1000"), $C5) + COUNTIFS(INDIRECT("Game Record!C2:C1000"), $A5, INDIRECT("Game Record!E2:E1000"), $C5)), 0) -> 120.56667 | K5: =IFERROR(I5/(G5+H5)) -> 125.52717
A6: Luke | B6: 5 | C6: 2019 | D6: =IF(A6 = "", "", COUNTIFS('Game Record'!G:G, A6, 'Game Record'!E:E, C6)) -> 11 | E6: =IF(A6 = "", "", COUNTIFS('Game Record'!H:H, A6, 'Game Record'!E:E, C6)) -> 4 | F6: =SUMIFS(INDIRECT("Game Record!B2:B1000"), INDIRECT("Game Record!A2:A1000"), A6, INDIRECT("Game Record!E2:E1000"), C6) + SUMIFS(INDIRECT("Game Record!D2:D1000"), INDIRECT("Game Record!C2:C1000"), A6, INDIRECT("Game Record!E2:E1000"), C6) -> 2149.05 | G6: =IF(A6 = "", "", COUNTIF('Game Record'!G:G, A6)) -> 24 | H6: =IF(A6 = "", "", COUNTIF('Game Record'!H:H, A6)) -> 22 | I6: =IFERROR(__xludf.DUMMYFUNCTION("SUM(FILTER(TeamARecordSet, INDEX(TeamARecordSet, 0, 1) = A6)) + SUM(FILTER(TeamBRecordSet, INDEX(TeamBRecordSet, 0, 1) = A6))"),6113.9) -> 6113.9 | J6: =IFERROR( (SUMIFS(INDIRECT("Game Record!B2:B1000"), INDIRECT("Game Record!A2:A1000"), $A6, INDIRECT("Game Record!E2:E1000"), $C6) + SUMIFS(INDIRECT("Game Record!D2:D1000"), INDIRECT("Game Record!C2:C1000"), $A6, INDIRECT("Game Record!E2:E1000"), $C6)) / (COUNTIFS(INDIRECT("Game Record!A2:A1000"), $A6, INDIRECT("Game Record!E2:E1000"), $C6) + COUNTIFS(INDIRECT("Game Record!C2:C1000"), $A6, INDIRECT("Game Record!E2:E1000"), $C6)), 0) -> 143.27 | K6: =IFERROR(I6/(G6+H6)) -> 132.91087
A7: Connor | B7: 6 | C7: 2019 | D7: =IF(A7 = "", "", COUNTIFS('Game Record'!G:G, A7, 'Game Record'!E:E, C7)) -> 9 | E7: =IF(A7 = "", "", COUNTIFS('Game Record'!H:H, A7, 'Game Record'!E:E, C7)) -> 6 | F7: =SUMIFS(INDIRECT("Game Record!B2:B1000"), INDIRECT("Game Record!A2:A1000"), A7, INDIRECT("Game Record!E2:E1000"), C7) + SUMIFS(INDIRECT("Game Record!D2:D1000"), INDIRECT("Game Record!C2:C1000"), A7, INDIRECT("Game Record!E2:E1000"), C7) -> 1932.5 | G7: =IF(A7 = "", "", COUNTIF('Game Record'!G:G, A7)) -> 22 | H7: =IF(A7 = "", "", COUNTIF('Game Record'!H:H, A7)) -> 25 | I7: =IFERROR(__xludf.DUMMYFUNCTION("SUM(FILTER(TeamARecordSet, INDEX(TeamARecordSet, 0, 1) = A7)) + SUM(FILTER(TeamBRecordSet, INDEX(TeamBRecordSet, 0, 1) = A7))"),5792.75) -> 5792.75 | J7: =IFERROR( (SUMIFS(INDIRECT("Game Record!B2:B1000"), INDIRECT("Game Record!A2:A1000"), $A7, INDIRECT("Game Record!E2:E1000"), $C7) + SUMIFS(INDIRECT("Game Record!D2:D1000"), INDIRECT("Game Record!C2:C1000"), $A7, INDIRECT("Game Record!E2:E1000"), $C7)) / (COUNTIFS(INDIRECT("Game Record!A2:A1000"), $A7, INDIRECT("Game Record!E2:E1000"), $C7) + COUNTIFS(INDIRECT("Game Record!C2:C1000"), $A7, INDIRECT("Game Record!E2:E1000"), $C7)), 0) -> 128.83333 | K7: =IFERROR(I7/(G7+H7)) -> 123.25
A8: Michael | B8: 7 | C8: 2019 | D8: =IF(A8 = "", "", COUNTIFS('Game Record'!G:G, A8, 'Game Record'!E:E, C8)) -> 6 | E8: =IF(A8 = "", "", COUNTIFS('Game Record'!H:H, A8, 'Game Record'!E:E, C8)) -> 9 | F8: =SUMIFS(INDIRECT("Game Record!B2:B1000"), INDIRECT("Game Record!A2:A1000"), A8, INDIRECT("Game Record!E2:E1000"), C8) + SUMIFS(INDIRECT("Game Record!D2:D1000"), INDIRECT("Game Record!C2:C1000"), A8, INDIRECT("Game Record!E2:E1000"), C8) -> 1729.15 | G8: =IF(A8 = "", "", COUNTIF('Game Record'!G:G, A8)) -> 6 | H8: =IF(A8 = "", "", COUNTIF('Game Record'!H:H, A8)) -> 9 | I8: =IFERROR(__xludf.DUMMYFUNCTION("SUM(FILTER(TeamARecordSet, INDEX(TeamARecordSet, 0, 1) = A8)) + SUM(FILTER(TeamBRecordSet, INDEX(TeamBRecordSet, 0, 1) = A8))"),1729.1499999999999) -> 1729.15 | J8: =IFERROR( (SUMIFS(INDIRECT("Game Record!B2:B1000"), INDIRECT("Game Record!A2:A1000"), $A8, INDIRECT("Game Record!E2:E1000"), $C8) + SUMIFS(INDIRECT("Game Record!D2:D1000"), INDIRECT("Game Record!C2:C1000"), $A8, INDIRECT("Game Record!E2:E1000"), $C8)) / (COUNTIFS(INDIRECT("Game Record!A2:A1000"), $A8, INDIRECT("Game Record!E2:E1000"), $C8) + COUNTIFS(INDIRECT("Game Record!C2:C1000"), $A8, INDIRECT("Game Record!E2:E1000"), $C8)), 0) -> 115.27667 | K8: =IFERROR(I8/(G8+H8)) -> 115.27667
A9: Raghav | B9: 8 | C9: 2019 | D9: =IF(A9 = "", "", COUNTIFS('Game Record'!G:G, A9, 'Game Record'!E:E, C9)) -> 6 | E9: =IF(A9 = "", "", COUNTIFS('Game Record'!H:H, A9, 'Game Record'!E:E, C9)) -> 9 | F9: =SUMIFS(INDIRECT("Game Record!B2:B1000"), INDIRECT("Game Record!A2:A1000"), A9, INDIRECT("Game Record!E2:E1000"), C9) + SUMIFS(INDIRECT("Game Record!D2:D1000"), INDIRECT("Game Record!C2:C1000"), A9, INDIRECT("Game Record!E2:E1000"), C9) -> 1718.05 | G9: =IF(A9 = "", "", COUNTIF('Game Record'!G:G, A9)) -> 6 | H9: =IF(A9 = "", "", COUNTIF('Game Record'!H:H, A9)) -> 9 | I9: =IFERROR(__xludf.DUMMYFUNCTION("SUM(FILTER(TeamARecordSet, INDEX(TeamARecordSet, 0, 1) = A9)) + SUM(FILTER(TeamBRecordSet, INDEX(TeamBRecordSet, 0, 1) = A9))"),1718.05) -> 1718.05 | J9: =IFERROR( (SUMIFS(INDIRECT("Game Record!B2:B1000"), INDIRECT("Game Record!A2:A1000"), $A9, INDIRECT("Game Record!E2:E1000"), $C9) + SUMIFS(INDIRECT("Game Record!D2:D1000"), INDIRECT("Game Record!C2:C1000"), $A9, INDIRECT("Game Record!E2:E1000"), $C9)) / (COUNTIFS(INDIRECT("Game Record!A2:A1000"), $A9, INDIRECT("Game Record!E2:E1000"), $C9) + COUNTIFS(INDIRECT("Game Record!C2:C1000"), $A9, INDIRECT("Game Record!E2:E1000"), $C9)), 0) -> 114.53667 | K9: =IFERROR(I9/(G9+H9)) -> 114.53667
A10: Kyle | B10: 9 | C10: 2019 | D10: =IF(A10 = "", "", COUNTIFS('Game Record'!G:G, A10, 'Game Record'!E:E, C10)) -> 5 | E10: =IF(A10 = "", "", COUNTIFS('Game Record'!H:H, A10, 'Game Record'!E:E, C10)) -> 10 | F10: =SUMIFS(INDIRECT("Game Record!B2:B1000"), INDIRECT("Game Record!A2:A1000"), A10, INDIRECT("Game Record!E2:E1000"), C10) + SUMIFS(INDIRECT("Game Record!D2:D1000"), INDIRECT("Game Record!C2:C1000"), A10, INDIRECT("Game Record!E2:E1000"), C10) -> 1653.3 | G10: =IF(A10 = "", "", COUNTIF('Game Record'!G:G, A10)) -> 24 | H10: =IF(A10 = "", "", COUNTIF('Game Record'!H:H, A10)) -> 23 | I10: =IFERROR(__xludf.DUMMYFUNCTION("SUM(FILTER(TeamARecordSet, INDEX(TeamARecordSet, 0, 1) = A10)) + SUM(FILTER(TeamBRecordSet, INDEX(TeamBRecordSet, 0, 1) = A10))"),5701.35) -> 5701.35 | J10: =IFERROR( (SUMIFS(INDIRECT("Game Record!B2:B1000"), INDIRECT("Game Record!A2:A1000"), $A10, INDIRECT("Game Record!E2:E1000"), $C10) + SUMIFS(INDIRECT("Game Record!D2:D1000"), INDIRECT("Game Record!C2:C1000"), $A10, INDIRECT("Game Record!E2:E1000"), $C10)) / (COUNTIFS(INDIRECT("Game Record!A2:A1000"), $A10, INDIRECT("Game Record!E2:E1000"), $C10) + COUNTIFS(INDIRECT("Game Record!C2:C1000"), $A10, INDIRECT("Game Record!E2:E1000"), $C10)), 0) -> 110.22 | K10: =IFERROR(I10/(G10+H10)) -> 121.30532
A11: Ruben | B11: 10 | C11: 2019 | D11: =IF(A11 = "", "", COUNTIFS('Game Record'!G:G, A11, 'Game Record'!E:E, C11)) -> 4 | E11: =IF(A11 = "", "", COUNTIFS('Game Record'!H:H, A11, 'Game Record'!E:E, C11)) -> 11 | F11: =SUMIFS(INDIRECT("Game Record!B2:B1000"), INDIRECT("Game Record!A2:A1000"), A11, INDIRECT("Game Record!E2:E1000"), C11) + SUMIFS(INDIRECT("Game Record!D2:D1000"), INDIRECT("Game Record!C2:C1000"), A11, INDIRECT("Game Record!E2:E1000"), C11) -> 1524.8 | G11: =IF(A11 = "", "", COUNTIF('Game Record'!G:G, A11)) -> 13 | H11: =IF(A11 = "", "", COUNTIF('Game Record'!H:H, A11)) -> 33 | I11: =IFERROR(__xludf.DUMMYFUNCTION("SUM(FILTER(TeamARecordSet, INDEX(TeamARecordSet, 0, 1) = A11)) + SUM(FILTER(TeamBRecordSet, INDEX(TeamBRecordSet, 0, 1) = A11))"),5045.25) -> 5045.25 | J11: =IFERROR( (SUMIFS(INDIRECT("Game Record!B2:B1000"), INDIRECT("Game Record!A2:A1000"), $A11, INDIRECT("Game Record!E2:E1000"), $C11) + SUMIFS(INDIRECT("Game Record!D2:D1000"), INDIRECT("Game Record!C2:C1000"), $A11, INDIRECT("Game Record!E2:E1000"), $C11)) / (COUNTIFS(INDIRECT("Game Record!A2:A1000"), $A11, INDIRECT("Game Record!E2:E1000"), $C11) + COUNTIFS(INDIRECT("Game Record!C2:C1000"), $A11, INDIRECT("Game Record!E2:E1000"), $C11)), 0) -> 101.65333 | K11: =IFERROR(I11/(G11+H11)) -> 109.67935
A12: Griffin | B12: 3 | C12: 2020 | D12: =IF(A12 = "", "", COUNTIFS('Game Record'!G:G, A12, 'Game Record'!E:E, C12)) -> 10 | E12: =IF(A12 = "", "", COUNTIFS('Game Record'!H:H, A12, 'Game Record'!E:E, C12)) -> 5 | F12: =SUMIFS(INDIRECT("Game Record!B2:B1000"), INDIRECT("Game Record!A2:A1000"), A12, INDIRECT("Game Record!E2:E1000"), C12) + SUMIFS(INDIRECT("Game Record!D2:D1000"), INDIRECT("Game Record!C2:C1000"), A12, INDIRECT("Game Record!E2:E1000"), C12) -> 2173.1 | G12: =IF(A12 = "", "", COUNTIF('Game Record'!G:G, A12)) -> 28 | H12: =IF(A12 = "", "", COUNTIF('Game Record'!H:H, A12)) -> 20 | I12: =IFERROR(__xludf.DUMMYFUNCTION("SUM(FILTER(TeamARecordSet, INDEX(TeamARecordSet, 0, 1) = A12)) + SUM(FILTER(TeamBRecordSet, INDEX(TeamBRecordSet, 0, 1) = A12))"),6498.450000000001) -> 6498.45 | J12: =IFERROR( (SUMIFS(INDIRECT("Game Record!B2:B1000"), INDIRECT("Game Record!A2:A1000"), $A12, INDIRECT("Game Record!E2:E1000"), $C12) + SUMIFS(INDIRECT("Game Record!D2:D1000"), INDIRECT("Game Record!C2:C1000"), $A12, INDIRECT("Game Record!E2:E1000"), $C12)) / (COUNTIFS(INDIRECT("Game Record!A2:A1000"), $A12, INDIRECT("Game Record!E2:E1000"), $C12) + COUNTIFS(INDIRECT("Game Record!C2:C1000"), $A12, INDIRECT("Game Record!E2:E1000"), $C12)), 0) -> 144.87333 | K12: =IFERROR(I12/(G12+H12)) -> 135.38438
A13: Jacob | B13: 1 | C13: 2020 | D13: =IF(A13 = "", "", COUNTIFS('Game Record'!G:G, A13, 'Game Record'!E:E, C13)) -> 11 | E13: =IF(A13 = "", "", COUNTIFS('Game Record'!H:H, A13, 'Game Record'!E:E, C13)) -> 4 | F13: =SUMIFS(INDIRECT("Game Record!B2:B1000"), INDIRECT("Game Record!A2:A1000"), A13, INDIRECT("Game Record!E2:E1000"), C13) + SUMIFS(INDIRECT("Game Record!D2:D1000"), INDIRECT("Game Record!C2:C1000"), A13, INDIRECT("Game Record!E2:E1000"), C13) -> 2025.15 | G13: =IF(A13 = "", "", COUNTIF('Game Record'!G:G, A13)) -> 31 | H13: =IF(A13 = "", "", COUNTIF('Game Record'!H:H, A13)) -> 15 | I13: =IFERROR(__xludf.DUMMYFUNCTION("SUM(FILTER(TeamARecordSet, INDEX(TeamARecordSet, 0, 1) = A13)) + SUM(FILTER(TeamBRecordSet, INDEX(TeamBRecordSet, 0, 1) = A13))"),5915.15) -> 5915.15 | J13: =IFERROR( (SUMIFS(INDIRECT("Game Record!B2:B1000"), INDIRECT("Game Record!A2:A1000"), $A13, INDIRECT("Game Record!E2:E1000"), $C13) + SUMIFS(INDIRECT("Game Record!D2:D1000"), INDIRECT("Game Record!C2:C1000"), $A13, INDIRECT("Game Record!E2:E1000"), $C13)) / (COUNTIFS(INDIRECT("Game Record!A2:A1000"), $A13, INDIRECT("Game Record!E2:E1000"), $C13) + COUNTIFS(INDIRECT("Game Record!C2:C1000"), $A13, INDIRECT("Game Record!E2:E1000"), $C13)), 0) -> 135.01 | K13: =IFERROR(I13/(G13+H13)) -> 128.59022
A14: Luke | B14: 8 | C14: 2020 | D14: =IF(A14 = "", "", COUNTIFS('Game Record'!G:G, A14, 'Game Record'!E:E, C14)) -> 5 | E14: =IF(A14 = "", "", COUNTIFS('Game Record'!H:H, A14, 'Game Record'!E:E, C14)) -> 10 | F14: =SUMIFS(INDIRECT("Game Record!B2:B1000"), INDIRECT("Game Record!A2:A1000"), A14, INDIRECT("Game Record!E2:E1000"), C14) + SUMIFS(INDIRECT("Game Record!D2:D1000"), INDIRECT("Game Record!C2:C1000"), A14, INDIRECT("Game Record!E2:E1000"), C14) -> 1837 | G14: =IF(A14 = "", "", COUNTIF('Game Record'!G:G, A14)) -> 24 | H14: =IF(A14 = "", "", COUNTIF('Game Record'!H:H, A14)) -> 22 | I14: =IFERROR(__xludf.DUMMYFUNCTION("SUM(FILTER(TeamARecordSet, INDEX(TeamARecordSet, 0, 1) = A14)) + SUM(FILTER(TeamBRecordSet, INDEX(TeamBRecordSet, 0, 1) = A14))"),6113.9) -> 6113.9 | J14: =IFERROR( (SUMIFS(INDIRECT("Game Record!B2:B1000"), INDIRECT("Game Record!A2:A1000"), $A14, INDIRECT("Game Record!E2:E1000"), $C14) + SUMIFS(INDIRECT("Game Record!D2:D1000"), INDIRECT("Game Record!C2:C1000"), $A14, INDIRECT("Game Record!E2:E1000"), $C14)) / (COUNTIFS(INDIRECT("Game Record!A2:A1000"), $A14, INDIRECT("Game Record!E2:E1000"), $C14) + COUNTIFS(INDIRECT("Game Record!C2:C1000"), $A14, INDIRECT("Game Record!E2:E1000"), $C14)), 0) -> 122.46667 | K14: =IFERROR(I14/(G14+H14)) -> 132.91087
A15: Kadin | B15: 2 | C15: 2020 | D15: =IF(A15 = "", "", COUNTIFS('Game Record'!G:G, A15, 'Game Record'!E:E, C15)) -> 8 | E15: =IF(A15 = "", "", COUNTIFS('Game Record'!H:H, A15, 'Game Record'!E:E, C15)) -> 8 | F15: =SUMIFS(INDIRECT("Game Record!B2:B1000"), INDIRECT("Game Record!A2:A1000"), A15, INDIRECT("Game Record!E2:E1000"), C15) + SUMIFS(INDIRECT("Game Record!D2:D1000"), INDIRECT("Game Record!C2:C1000"), A15, INDIRECT("Game Record!E2:E1000"), C15) -> 2022 | G15: =IF(A15 = "", "", COUNTIF('Game Record'!G:G, A15)) -> 27 | H15: =IF(A15 = "", "", COUNTIF('Game Record'!H:H, A15)) -> 21 | I15: =IFERROR(__xludf.DUMMYFUNCTION("SUM(FILTER(TeamARecordSet, INDEX(TeamARecordSet, 0, 1) = A15)) + SUM(FILTER(TeamBRecordSet, INDEX(TeamBRecordSet, 0, 1) = A15))"),6585.0999999999985) -> 6585.1 | J15: =IFERROR( (SUMIFS(INDIRECT("Game Record!B2:B1000"), INDIRECT("Game Record!A2:A1000"), $A15, INDIRECT("Game Record!E2:E1000"), $C15) + SUMIFS(INDIRECT("Game Record!D2:D1000"), INDIRECT("Game Record!C2:C1000"), $A15, INDIRECT("Game Record!E2:E1000"), $C15)) / (COUNTIFS(INDIRECT("Game Record!A2:A1000"), $A15, INDIRECT("Game Record!E2:E1000"), $C15) + COUNTIFS(INDIRECT("Game Record!C2:C1000"), $A15, INDIRECT("Game Record!E2:E1000"), $C15)), 0) -> 126.375 | K15: =IFERROR(I15/(G15+H15)) -> 137.18958
A16: Ruben | B16: 10 | C16: 2020 | D16: =IF(A16 = "", "", COUNTIFS('Game Record'!G:G, A16, 'Game Record'!E:E, C16)) -> 6 | E16: =IF(A16 = "", "", COUNTIFS('Game Record'!H:H, A16, 'Game Record'!E:E, C16)) -> 9 | F16: =SUMIFS(INDIRECT("Game Record!B2:B1000"), INDIRECT("Game Record!A2:A1000"), A16, INDIRECT("Game Record!E2:E1000"), C16) + SUMIFS(INDIRECT("Game Record!D2:D1000"), INDIRECT("Game Record!C2:C1000"), A16, INDIRECT("Game Record!E2:E1000"), C16) -> 1886.05 | G16: =IF(A16 = "", "", COUNTIF('Game Record'!G:G, A16)) -> 13 | H16: =IF(A16 = "", "", COUNTIF('Game Record'!H:H, A16)) -> 33 | I16: =IFERROR(__xludf.DUMMYFUNCTION("SUM(FILTER(TeamARecordSet, INDEX(TeamARecordSet, 0, 1) = A16)) + SUM(FILTER(TeamBRecordSet, INDEX(TeamBRecordSet, 0, 1) = A16))"),5045.25) -> 5045.25 | J16: =IFERROR( (SUMIFS(INDIRECT("Game Record!B2:B1000"), INDIRECT("Game Record!A2:A1000"), $A16, INDIRECT("Game Record!E2:E1000"), $C16) + SUMIFS(INDIRECT("Game Record!D2:D1000"), INDIRECT("Game Record!C2:C1000"), $A16, INDIRECT("Game Record!E2:E1000"), $C16)) / (COUNTIFS(INDIRECT("Game Record!A2:A1000"), $A16, INDIRECT("Game Record!E2:E1000"), $C16) + COUNTIFS(INDIRECT("Game Record!C2:C1000"), $A16, INDIRECT("Game Record!E2:E1000"), $C16)), 0) -> 125.73667 | K16: =IFERROR(I16/(G16+H16)) -> 109.67935
A17: Mitch | B17: 6 | C17: 2020 | D17: =IF(A17 = "", "", COUNTIFS('Game Record'!G:G, A17, 'Game Record'!E:E, C17)) -> 6 | E17: =IF(A17 = "", "", COUNTIFS('Game Record'!H:H, A17, 'Game Record'!E:E, C17)) -> 9 | F17: =SUMIFS(INDIRECT("Game Record!B2:B1000"), INDIRECT("Game Record!A2:A1000"), A17, INDIRECT("Game Record!E2:E1000"), C17) + SUMIFS(INDIRECT("Game Record!D2:D1000"), INDIRECT("Game Record!C2:C1000"), A17, INDIRECT("Game Record!E2:E1000"), C17) -> 1740.45 | G17: =IF(A17 = "", "", COUNTIF('Game Record'!G:G, A17)) -> 22 | H17: =IF(A17 = "", "", COUNTIF('Game Record'!H:H, A17)) -> 24 | I17: =IFERROR(__xludf.DUMMYFUNCTION("SUM(FILTER(TeamARecordSet, INDEX(TeamARecordSet, 0, 1) = A17)) + SUM(FILTER(TeamBRecordSet, INDEX(TeamBRecordSet, 0, 1) = A17))"),5774.249999999999) -> 5774.25 | J17: =IFERROR( (SUMIFS(INDIRECT("Game Record!B2:B1000"), INDIRECT("Game Record!A2:A1000"), $A17, INDIRECT("Game Record!E2:E1000"), $C17) + SUMIFS(INDIRECT("Game Record!D2:D1000"), INDIRECT("Game Record!C2:C1000"), $A17, INDIRECT("Game Record!E2:E1000"), $C17)) / (COUNTIFS(INDIRECT("Game Record!A2:A1000"), $A17, INDIRECT("Game Record!E2:E1000"), $C17) + COUNTIFS(INDIRECT("Game Record!C2:C1000"), $A17, INDIRECT("Game Record!E2:E1000"), $C17)), 0) -> 116.03 | K17: =IFERROR(I17/(G17+H17)) -> 125.52717
A18: Andrew | B18: 7 | C18: 2020 | D18: =IF(A18 = "", "", COUNTIFS('Game Record'!G:G, A18, 'Game Record'!E:E, C18)) -> 5 | E18: =IF(A18 = "", "", COUNTIFS('Game Record'!H:H, A18, 'Game Record'!E:E, C18)) -> 10 | F18: =SUMIFS(INDIRECT("Game Record!B2:B1000"), INDIRECT("Game Record!A2:A1000"), A18, INDIRECT("Game Record!E2:E1000"), C18) + SUMIFS(INDIRECT("Game Record!D2:D1000"), INDIRECT("Game Record!C2:C1000"), A18, INDIRECT("Game Record!E2:E1000"), C18) -> 1806.8 | G18: =IF(A18 = "", "", COUNTIF('Game Record'!G:G, A18)) -> 15 | H18: =IF(A18 = "", "", COUNTIF('Game Record'!H:H, A18)) -> 16 | I18: =IFERROR(__xludf.DUMMYFUNCTION("SUM(FILTER(TeamARecordSet, INDEX(TeamARecordSet, 0, 1) = A18)) + SUM(FILTER(TeamBRecordSet, INDEX(TeamBRecordSet, 0, 1) = A18))"),3779.55) -> 3779.55 | J18: =IFERROR( (SUMIFS(INDIRECT("Game Record!B2:B1000"), INDIRECT("Game Record!A2:A1000"), $A18, INDIRECT("Game Record!E2:E1000"), $C18) + SUMIFS(INDIRECT("Game Record!D2:D1000"), INDIRECT("Game Record!C2:C1000"), $A18, INDIRECT("Game Record!E2:E1000"), $C18)) / (COUNTIFS(INDIRECT("Game Record!A2:A1000"), $A18, INDIRECT("Game Record!E2:E1000"), $C18) + COUNTIFS(INDIRECT("Game Record!C2:C1000"), $A18, INDIRECT("Game Record!E2:E1000"), $C18)), 0) -> 120.45333 | K18: =IFERROR(I18/(G18+H18)) -> 121.92097
A19: Nick | B19: 9 | C19: 2020 | D19: =IF(A19 = "", "", COUNTIFS('Game Record'!G:G, A19, 'Game Record'!E:E, C19)) -> 7 | E19: =IF(A19 = "", "", COUNTIFS('Game Record'!H:H, A19, 'Game Record'!E:E, C19)) -> 8 | F19: =SUMIFS(INDIRECT("Game Record!B2:B1000"), INDIRECT("Game Record!A2:A1000"), A19, INDIRECT("Game Record!E2:E1000"), C19) + SUMIFS(INDIRECT("Game Record!D2:D1000"), INDIRECT("Game Record!C2:C1000"), A19, INDIRECT("Game Record!E2:E1000"), C19) -> 1836.35 | G19: =IF(A19 = "", "", COUNTIF('Game Record'!G:G, A19)) -> 15 | H19: =IF(A19 = "", "", COUNTIF('Game Record'!H:H, A19)) -> 16 | I19: =IFERROR(__xludf.DUMMYFUNCTION("SUM(FILTER(TeamARecordSet, INDEX(TeamARecordSet, 0, 1) = A19)) + SUM(FILTER(TeamBRecordSet, INDEX(TeamBRecordSet, 0, 1) = A19))"),3759.1000000000004) -> 3759.1 | J19: =IFERROR( (SUMIFS(INDIRECT("Game Record!B2:B1000"), INDIRECT("Game Record!A2:A1000"), $A19, INDIRECT("Game Record!E2:E1000"), $C19) + SUMIFS(INDIRECT("Game Record!D2:D1000"), INDIRECT("Game Record!C2:C1000"), $A19, INDIRECT("Game Record!E2:E1000"), $C19)) / (COUNTIFS(INDIRECT("Game Record!A2:A1000"), $A19, INDIRECT("Game Record!E2:E1000"), $C19) + COUNTIFS(INDIRECT("Game Record!C2:C1000"), $A19, INDIRECT("Game Record!E2:E1000"), $C19)), 0) -> 122.42333 | K19: =IFERROR(I19/(G19+H19)) -> 121.26129
A20: Connor | B20: 4 | C20: 2020 | D20: =IF(A20 = "", "", COUNTIFS('Game Record'!G:G, A20, 'Game Record'!E:E, C20)) -> 9 | E20: =IF(A20 = "", "", COUNTIFS('Game Record'!H:H, A20, 'Game Record'!E:E, C20)) -> 7 | F20: =SUMIFS(INDIRECT("Game Record!B2:B1000"), INDIRECT("Game Record!A2:A1000"), A20, INDIRECT("Game Record!E2:E1000"), C20) + SUMIFS(INDIRECT("Game Record!D2:D1000"), INDIRECT("Game Record!C2:C1000"), A20, INDIRECT("Game Record!E2:E1000"), C20) -> 2013.2 | G20: =IF(A20 = "", "", COUNTIF('Game Record'!G:G, A20)) -> 22 | H20: =IF(A20 = "", "", COUNTIF('Game Record'!H:H, A20)) -> 25 | I20: =IFERROR(__xludf.DUMMYFUNCTION("SUM(FILTER(TeamARecordSet, INDEX(TeamARecordSet, 0, 1) = A20)) + SUM(FILTER(TeamBRecordSet, INDEX(TeamBRecordSet, 0, 1) = A20))"),5792.75) -> 5792.75 | J20: =IFERROR( (SUMIFS(INDIRECT("Game Record!B2:B1000"), INDIRECT("Game Record!A2:A1000"), $A20, INDIRECT("Game Record!E2:E1000"), $C20) + SUMIFS(INDIRECT("Game Record!D2:D1000"), INDIRECT("Game Record!C2:C1000"), $A20, INDIRECT("Game Record!E2:E1000"), $C20)) / (COUNTIFS(INDIRECT("Game Record!A2:A1000"), $A20, INDIRECT("Game Record!E2:E1000"), $C20) + COUNTIFS(INDIRECT("Game Record!C2:C1000"), $A20, INDIRECT("Game Record!E2:E1000"), $C20)), 0) -> 125.825 | K20: =IFERROR(I20/(G20+H20)) -> 123.25
A21: Kyle | B21: 5 | C21: 2020 | D21: =IF(A21 = "", "", COUNTIFS('Game Record'!G:G, A21, 'Game Record'!E:E, C21)) -> 9 | E21: =IF(A21 = "", "", COUNTIFS('Game Record'!H:H, A21, 'Game Record'!E:E, C21)) -> 6 | F21: =SUMIFS(INDIRECT("Game Record!B2:B1000"), INDIRECT("Game Record!A2:A1000"), A21, INDIRECT("Game Record!E2:E1000"), C21) + SUMIFS(INDIRECT("Game Record!D2:D1000"), INDIRECT("Game Record!C2:C1000"), A21, INDIRECT("Game Record!E2:E1000"), C21) -> 1816.5 | G21: =IF(A21 = "", "", COUNTIF('Game Record'!G:G, A21)) -> 24 | H21: =IF(A21 = "", "", COUNTIF('Game Record'!H:H, A21)) -> 23 | I21: =IFERROR(__xludf.DUMMYFUNCTION("SUM(FILTER(TeamARecordSet, INDEX(TeamARecordSet, 0, 1) = A21)) + SUM(FILTER(TeamBRecordSet, INDEX(TeamBRecordSet, 0, 1) = A21))"),5701.35) -> 5701.35 | J21: =IFERROR( (SUMIFS(INDIRECT("Game Record!B2:B1000"), INDIRECT("Game Record!A2:A1000"), $A21, INDIRECT("Game Record!E2:E1000"), $C21) + SUMIFS(INDIRECT("Game Record!D2:D1000"), INDIRECT("Game Record!C2:C1000"), $A21, INDIRECT("Game Record!E2:E1000"), $C21)) / (COUNTIFS(INDIRECT("Game Record!A2:A1000"), $A21, INDIRECT("Game Record!E2:E1000"), $C21) + COUNTIFS(INDIRECT("Game Record!C2:C1000"), $A21, INDIRECT("Game Record!E2:E1000"), $C21)), 0) -> 121.1 | K21: =IFERROR(I21/(G21+H21)) -> 121.30532
A22: Luke | B22: 8 | C22: 2021 | D22: =IF(A22 = "", "", COUNTIFS('Game Record'!G:G, A22, 'Game Record'!E:E, C22)) -> 8 | E22: =IF(A22 = "", "", COUNTIFS('Game Record'!H:H, A22, 'Game Record'!E:E, C22)) -> 8 | F22: =SUMIFS(INDIRECT("Game Record!B2:B1000"), INDIRECT("Game Record!A2:A1000"), A22, INDIRECT("Game Record!E2:E1000"), C22) + SUMIFS(INDIRECT("Game Record!D2:D1000"), INDIRECT("Game Record!C2:C1000"), A22, INDIRECT("Game Record!E2:E1000"), C22) -> 2127.85 | G22: =IF(A22 = "", "", COUNTIF('Game Record'!G:G, A22)) -> 24 | H22: =IF(A22 = "", "", COUNTIF('Game Record'!H:H, A22)) -> 22 | I22: =IFERROR(__xludf.DUMMYFUNCTION("SUM(FILTER(TeamARecordSet, INDEX(TeamARecordSet, 0, 1) = A22)) + SUM(FILTER(TeamBRecordSet, INDEX(TeamBRecordSet, 0, 1) = A22))"),6113.9) -> 6113.9 | J22: =IFERROR( (SUMIFS(INDIRECT("Game Record!B2:B1000"), INDIRECT("Game Record!A2:A1000"), $A22, INDIRECT("Game Record!E2:E1000"), $C22) + SUMIFS(INDIRECT("Game Record!D2:D1000"), INDIRECT("Game Record!C2:C1000"), $A22, INDIRECT("Game Record!E2:E1000"), $C22)) / (COUNTIFS(INDIRECT("Game Record!A2:A1000"), $A22, INDIRECT("Game Record!E2:E1000"), $C22) + COUNTIFS(INDIRECT("Game Record!C2:C1000"), $A22, INDIRECT("Game Record!E2:E1000"), $C22)), 0) -> 132.99062 | K22: =IFERROR(I22/(G22+H22)) -> 132.91087
A23: Kadin | B23: 1 | C23: 2021 | D23: =IF(A23 = "", "", COUNTIFS('Game Record'!G:G, A23, 'Game Record'!E:E, C23)) -> 11 | E23: =IF(A23 = "", "", COUNTIFS('Game Record'!H:H, A23, 'Game Record'!E:E, C23)) -> 5 | F23: =SUMIFS(INDIRECT("Game Record!B2:B1000"), INDIRECT("Game Record!A2:A1000"), A23, INDIRECT("Game Record!E2:E1000"), C23) + SUMIFS(INDIRECT("Game Record!D2:D1000"), INDIRECT("Game Record!C2:C1000"), A23, INDIRECT("Game Record!E2:E1000"), C23) -> 2288.75 | G23: =IF(A23 = "", "", COUNTIF('Game Record'!G:G, A23)) -> 27 | H23: =IF(A23 = "", "", COUNTIF('Game Record'!H:H, A23)) -> 21 | I23: =IFERROR(__xludf.DUMMYFUNCTION("SUM(FILTER(TeamARecordSet, INDEX(TeamARecordSet, 0, 1) = A23)) + SUM(FILTER(TeamBRecordSet, INDEX(TeamBRecordSet, 0, 1) = A23))"),6585.0999999999985) -> 6585.1 | J23: =IFERROR( (SUMIFS(INDIRECT("Game Record!B2:B1000"), INDIRECT("Game Record!A2:A1000"), $A23, INDIRECT("Game Record!E2:E1000"), $C23) + SUMIFS(INDIRECT("Game Record!D2:D1000"), INDIRECT("Game Record!C2:C1000"), $A23, INDIRECT("Game Record!E2:E1000"), $C23)) / (COUNTIFS(INDIRECT("Game Record!A2:A1000"), $A23, INDIRECT("Game Record!E2:E1000"), $C23) + COUNTIFS(INDIRECT("Game Record!C2:C1000"), $A23, INDIRECT("Game Record!E2:E1000"), $C23)), 0) -> 143.04688 | K23: =IFERROR(I23/(G23+H23)) -> 137.18958
A24: Griffin | B24: 4 | C24: 2021 | D24: =IF(A24 = "", "", COUNTIFS('Game Record'!G:G, A24, 'Game Record'!E:E, C24)) -> 10 | E24: =IF(A24 = "", "", COUNTIFS('Game Record'!H:H, A24, 'Game Record'!E:E, C24)) -> 7 | F24: =SUMIFS(INDIRECT("Game Record!B2:B1000"), INDIRECT("Game Record!A2:A1000"), A24, INDIRECT("Game Record!E2:E1000"), C24) + SUMIFS(INDIRECT("Game Record!D2:D1000"), INDIRECT("Game Record!C2:C1000"), A24, INDIRECT("Game Record!E2:E1000"), C24) -> 2234.55 | G24: =IF(A24 = "", "", COUNTIF('Game Record'!G:G, A24)) -> 28 | H24: =IF(A24 = "", "", COUNTIF('Game Record'!H:H, A24)) -> 20 | I24: =IFERROR(__xludf.DUMMYFUNCTION("SUM(FILTER(TeamARecordSet, INDEX(TeamARecordSet, 0, 1) = A24)) + SUM(FILTER(TeamBRecordSet, INDEX(TeamBRecordSet, 0, 1) = A24))"),6498.450000000001) -> 6498.45 | J24: =IFERROR( (SUMIFS(INDIRECT("Game Record!B2:B1000"), INDIRECT("Game Record!A2:A1000"), $A24, INDIRECT("Game Record!E2:E1000"), $C24) + SUMIFS(INDIRECT("Game Record!D2:D1000"), INDIRECT("Game Record!C2:C1000"), $A24, INDIRECT("Game Record!E2:E1000"), $C24)) / (COUNTIFS(INDIRECT("Game Record!A2:A1000"), $A24, INDIRECT("Game Record!E2:E1000"), $C24) + COUNTIFS(INDIRECT("Game Record!C2:C1000"), $A24, INDIRECT("Game Record!E2:E1000"), $C24)), 0) -> 131.44412 | K24: =IFERROR(I24/(G24+H24)) -> 135.38438
A25: Ruben | B25: 10 | C25: 2021 | D25: =IF(A25 = "", "", COUNTIFS('Game Record'!G:G, A25, 'Game Record'!E:E, C25)) -> 3 | E25: =IF(A25 = "", "", COUNTIFS('Game Record'!H:H, A25, 'Game Record'!E:E, C25)) -> 13 | F25: =SUMIFS(INDIRECT("Game Record!B2:B1000"), INDIRECT("Game Record!A2:A1000"), A25, INDIRECT("Game Record!E2:E1000"), C25) + SUMIFS(INDIRECT("Game Record!D2:D1000"), INDIRECT("Game Record!C2:C1000"), A25, INDIRECT("Game Record!E2:E1000"), C25) -> 1634.4 | G25: =IF(A25 = "", "", COUNTIF('Game Record'!G:G, A25)) -> 13 | H25: =IF(A25 = "", "", COUNTIF('Game Record'!H:H, A25)) -> 33 | I25: =IFERROR(__xludf.DUMMYFUNCTION("SUM(FILTER(TeamARecordSet, INDEX(TeamARecordSet, 0, 1) = A25)) + SUM(FILTER(TeamBRecordSet, INDEX(TeamBRecordSet, 0, 1) = A25))"),5045.25) -> 5045.25 | J25: =IFERROR( (SUMIFS(INDIRECT("Game Record!B2:B1000"), INDIRECT("Game Record!A2:A1000"), $A25, INDIRECT("Game Record!E2:E1000"), $C25) + SUMIFS(INDIRECT("Game Record!D2:D1000"), INDIRECT("Game Record!C2:C1000"), $A25, INDIRECT("Game Record!E2:E1000"), $C25)) / (COUNTIFS(INDIRECT("Game Record!A2:A1000"), $A25, INDIRECT("Game Record!E2:E1000"), $C25) + COUNTIFS(INDIRECT("Game Record!C2:C1000"), $A25, INDIRECT("Game Record!E2:E1000"), $C25)), 0) -> 102.15 | K25: =IFERROR(I25/(G25+H25)) -> 109.67935
A26: Mitch | B26: 5 | C26: 2021 | D26: =IF(A26 = "", "", COUNTIFS('Game Record'!G:G, A26, 'Game Record'!E:E, C26)) -> 8 | E26: =IF(A26 = "", "", COUNTIFS('Game Record'!H:H, A26, 'Game Record'!E:E, C26)) -> 8 | F26: =SUMIFS(INDIRECT("Game Record!B2:B1000"), INDIRECT("Game Record!A2:A1000"), A26, INDIRECT("Game Record!E2:E1000"), C26) + SUMIFS(INDIRECT("Game Record!D2:D1000"), INDIRECT("Game Record!C2:C1000"), A26, INDIRECT("Game Record!E2:E1000"), C26) -> 2225.3 | G26: =IF(A26 = "", "", COUNTIF('Game Record'!G:G, A26)) -> 22 | H26: =IF(A26 = "", "", COUNTIF('Game Record'!H:H, A26)) -> 24 | I26: =IFERROR(__xludf.DUMMYFUNCTION("SUM(FILTER(TeamARecordSet, INDEX(TeamARecordSet, 0, 1) = A26)) + SUM(FILTER(TeamBRecordSet, INDEX(TeamBRecordSet, 0, 1) = A26))"),5774.249999999999) -> 5774.25 | J26: =IFERROR( (SUMIFS(INDIRECT("Game Record!B2:B1000"), INDIRECT("Game Record!A2:A1000"), $A26, INDIRECT("Game Record!E2:E1000"), $C26) + SUMIFS(INDIRECT("Game Record!D2:D1000"), INDIRECT("Game Record!C2:C1000"), $A26, INDIRECT("Game Record!E2:E1000"), $C26)) / (COUNTIFS(INDIRECT("Game Record!A2:A1000"), $A26, INDIRECT("Game Record!E2:E1000"), $C26) + COUNTIFS(INDIRECT("Game Record!C2:C1000"), $A26, INDIRECT("Game Record!E2:E1000"), $C26)), 0) -> 139.08125 | K26: =IFERROR(I26/(G26+H26)) -> 125.52717
A27: Jacob | B27: 6 | C27: 2021 | D27: =IF(A27 = "", "", COUNTIFS('Game Record'!G:G, A27, 'Game Record'!E:E, C27)) -> 9 | E27: =IF(A27 = "", "", COUNTIFS('Game Record'!H:H, A27, 'Game Record'!E:E, C27)) -> 7 | F27: =SUMIFS(INDIRECT("Game Record!B2:B1000"), INDIRECT("Game Record!A2:A1000"), A27, INDIRECT("Game Record!E2:E1000"), C27) + SUMIFS(INDIRECT("Game Record!D2:D1000"), INDIRECT("Game Record!C2:C1000"), A27, INDIRECT("Game Record!E2:E1000"), C27) -> 1900.55 | G27: =IF(A27 = "", "", COUNTIF('Game Record'!G:G, A27)) -> 31 | H27: =IF(A27 = "", "", COUNTIF('Game Record'!H:H, A27)) -> 15 | I27: =IFERROR(__xludf.DUMMYFUNCTION("SUM(FILTER(TeamARecordSet, INDEX(TeamARecordSet, 0, 1) = A27)) + SUM(FILTER(TeamBRecordSet, INDEX(TeamBRecordSet, 0, 1) = A27))"),5915.15) -> 5915.15 | J27: =IFERROR( (SUMIFS(INDIRECT("Game Record!B2:B1000"), INDIRECT("Game Record!A2:A1000"), $A27, INDIRECT("Game Record!E2:E1000"), $C27) + SUMIFS(INDIRECT("Game Record!D2:D1000"), INDIRECT("Game Record!C2:C1000"), $A27, INDIRECT("Game Record!E2:E1000"), $C27)) / (COUNTIFS(INDIRECT("Game Record!A2:A1000"), $A27, INDIRECT("Game Record!E2:E1000"), $C27) + COUNTIFS(INDIRECT("Game Record!C2:C1000"), $A27, INDIRECT("Game Record!E2:E1000"), $C27)), 0) -> 118.78437 | K27: =IFERROR(I27/(G27+H27)) -> 128.59022
A28: Andrew | B28: 2 | C28: 2021 | D28: =IF(A28 = "", "", COUNTIFS('Game Record'!G:G, A28, 'Game Record'!E:E, C28)) -> 10 | E28: =IF(A28 = "", "", COUNTIFS('Game Record'!H:H, A28, 'Game Record'!E:E, C28)) -> 6 | F28: =SUMIFS(INDIRECT("Game Record!B2:B1000"), INDIRECT("Game Record!A2:A1000"), A28, INDIRECT("Game Record!E2:E1000"), C28) + SUMIFS(INDIRECT("Game Record!D2:D1000"), INDIRECT("Game Record!C2:C1000"), A28, INDIRECT("Game Record!E2:E1000"), C28) -> 1972.75 | G28: =IF(A28 = "", "", COUNTIF('Game Record'!G:G, A28)) -> 15 | H28: =IF(A28 = "", "", COUNTIF('Game Record'!H:H, A28)) -> 16 | I28: =IFERROR(__xludf.DUMMYFUNCTION("SUM(FILTER(TeamARecordSet, INDEX(TeamARecordSet, 0, 1) = A28)) + SUM(FILTER(TeamBRecordSet, INDEX(TeamBRecordSet, 0, 1) = A28))"),3779.55) -> 3779.55 | J28: =IFERROR( (SUMIFS(INDIRECT("Game Record!B2:B1000"), INDIRECT("Game Record!A2:A1000"), $A28, INDIRECT("Game Record!E2:E1000"), $C28) + SUMIFS(INDIRECT("Game Record!D2:D1000"), INDIRECT("Game Record!C2:C1000"), $A28, INDIRECT("Game Record!E2:E1000"), $C28)) / (COUNTIFS(INDIRECT("Game Record!A2:A1000"), $A28, INDIRECT("Game Record!E2:E1000"), $C28) + COUNTIFS(INDIRECT("Game Record!C2:C1000"), $A28, INDIRECT("Game Record!E2:E1000"), $C28)), 0) -> 123.29688 | K28: =IFERROR(I28/(G28+H28)) -> 121.92097
A29: Connor | B29: 9 | C29: 2021 | D29: =IF(A29 = "", "", COUNTIFS('Game Record'!G:G, A29, 'Game Record'!E:E, C29)) -> 4 | E29: =IF(A29 = "", "", COUNTIFS('Game Record'!H:H, A29, 'Game Record'!E:E, C29)) -> 12 | F29: =SUMIFS(INDIRECT("Game Record!B2:B1000"), INDIRECT("Game Record!A2:A1000"), A29, INDIRECT("Game Record!E2:E1000"), C29) + SUMIFS(INDIRECT("Game Record!D2:D1000"), INDIRECT("Game Record!C2:C1000"), A29, INDIRECT("Game Record!E2:E1000"), C29) -> 1847.05 | G29: =IF(A29 = "", "", COUNTIF('Game Record'!G:G, A29)) -> 22 | H29: =IF(A29 = "", "", COUNTIF('Game Record'!H:H, A29)) -> 25 | I29: =IFERROR(__xludf.DUMMYFUNCTION("SUM(FILTER(TeamARecordSet, INDEX(TeamARecordSet, 0, 1) = A29)) + SUM(FILTER(TeamBRecordSet, INDEX(TeamBRecordSet, 0, 1) = A29))"),5792.75) -> 5792.75 | J29: =IFERROR( (SUMIFS(INDIRECT("Game Record!B2:B1000"), INDIRECT("Game Record!A2:A1000"), $A29, INDIRECT("Game Record!E2:E1000"), $C29) + SUMIFS(INDIRECT("Game Record!D2:D1000"), INDIRECT("Game Record!C2:C1000"), $A29, INDIRECT("Game Record!E2:E1000"), $C29)) / (COUNTIFS(INDIRECT("Game Record!A2:A1000"), $A29, INDIRECT("Game Record!E2:E1000"), $C29) + COUNTIFS(INDIRECT("Game Record!C2:C1000"), $A29, INDIRECT("Game Record!E2:E1000"), $C29)), 0) -> 115.44062 | K29: =IFERROR(I29/(G29+H29)) -> 123.25
A30: Kyle | B30: 3 | C30: 2021 | D30: =IF(A30 = "", "", COUNTIFS('Game Record'!G:G, A30, 'Game Record'!E:E, C30)) -> 10 | E30: =IF(A30 = "", "", COUNTIFS('Game Record'!H:H, A30, 'Game Record'!E:E, C30)) -> 7 | F30: =SUMIFS(INDIRECT("Game Record!B2:B1000"), INDIRECT("Game Record!A2:A1000"), A30, INDIRECT("Game Record!E2:E1000"), C30) + SUMIFS(INDIRECT("Game Record!D2:D1000"), INDIRECT("Game Record!C2:C1000"), A30, INDIRECT("Game Record!E2:E1000"), C30) -> 2231.55 | G30: =IF(A30 = "", "", COUNTIF('Game Record'!G:G, A30)) -> 24 | H30: =IF(A30 = "", "", COUNTIF('Game Record'!H:H, A30)) -> 23 | I30: =IFERROR(__xludf.DUMMYFUNCTION("SUM(FILTER(TeamARecordSet, INDEX(TeamARecordSet, 0, 1) = A30)) + SUM(FILTER(TeamBRecordSet, INDEX(TeamBRecordSet, 0, 1) = A30))"),5701.35) -> 5701.35 | J30: =IFERROR( (SUMIFS(INDIRECT("Game Record!B2:B1000"), INDIRECT("Game Record!A2:A1000"), $A30, INDIRECT("Game Record!E2:E1000"), $C30) + SUMIFS(INDIRECT("Game Record!D2:D1000"), INDIRECT("Game Record!C2:C1000"), $A30, INDIRECT("Game Record!E2:E1000"), $C30)) / (COUNTIFS(INDIRECT("Game Record!A2:A1000"), $A30, INDIRECT("Game Record!E2:E1000"), $C30) + COUNTIFS(INDIRECT("Game Record!C2:C1000"), $A30, INDIRECT("Game Record!E2:E1000"), $C30)), 0) -> 131.26765 | K30: =IFERROR(I30/(G30+H30)) -> 121.30532
A31: Nick | B31: 7 | C31: 2021 | D31: =IF(A31 = "", "", COUNTIFS('Game Record'!G:G, A31, 'Game Record'!E:E, C31)) -> 8 | E31: =IF(A31 = "", "", COUNTIFS('Game Record'!H:H, A31, 'Game Record'!E:E, C31)) -> 8 | F31: =SUMIFS(INDIRECT("Game Record!B2:B1000"), INDIRECT("Game Record!A2:A1000"), A31, INDIRECT("Game Record!E2:E1000"), C31) + SUMIFS(INDIRECT("Game Record!D2:D1000"), INDIRECT("Game Record!C2:C1000"), A31, INDIRECT("Game Record!E2:E1000"), C31) -> 1922.75 | G31: =IF(A31 = "", "", COUNTIF('Game Record'!G:G, A31)) -> 15 | H31: =IF(A31 = "", "", COUNTIF('Game Record'!H:H, A31)) -> 16 | I31: =IFERROR(__xludf.DUMMYFUNCTION("SUM(FILTER(TeamARecordSet, INDEX(TeamARecordSet, 0, 1) = A31)) + SUM(FILTER(TeamBRecordSet, INDEX(TeamBRecordSet, 0, 1) = A31))"),3759.1000000000004) -> 3759.1 | J31: =IFERROR( (SUMIFS(INDIRECT("Game Record!B2:B1000"), INDIRECT("Game Record!A2:A1000"), $A31, INDIRECT("Game Record!E2:E1000"), $C31) + SUMIFS(INDIRECT("Game Record!D2:D1000"), INDIRECT("Game Record!C2:C1000"), $A31, INDIRECT("Game Record!E2:E1000"), $C31)) / (COUNTIFS(INDIRECT("Game Record!A2:A1000"), $A31, INDIRECT("Game Record!E2:E1000"), $C31) + COUNTIFS(INDIRECT("Game Record!C2:C1000"), $A31, INDIRECT("Game Record!E2:E1000"), $C31)), 0) -> 120.17188 | K31: =IFERROR(I31/(G31+H31)) -> 121.26129
D32: =IF(A32 = "", "", COUNTIFS('Game Record'!G:G, A32, 'Game Record'!E:E, C32)) | E32: =IF(A32 = "", "", COUNTIFS('Game Record'!H:H, A32, 'Game Record'!E:E, C32)) | F32: =SUMIFS(INDIRECT("Game Record!B2:B1000"), INDIRECT("Game Record!A2:A1000"), A32, INDIRECT("Game Record!E2:E1000"), C32) + SUMIFS(INDIRECT("Game Record!D2:D1000"), INDIRECT("Game Record!C2:C1000"), A32, INDIRECT("Game Record!E2:E1000"), C32) -> 0 | G32: =IF(A32 = "", "", COUNTIF('Game Record'!G:G, A32)) | H32: =IF(A32 = "", "", COUNTIF('Game Record'!H:H, A32)) | I32: =IFERROR(__xludf.DUMMYFUNCTION("SUM(FILTER(TeamARecordSet, INDEX(TeamARecordSet, 0, 1) = A32)) + SUM(FILTER(TeamBRecordSet, INDEX(TeamBRecordSet, 0, 1) = A32))"),0.0) -> 0 | J32: =IFERROR( (SUMIFS(INDIRECT("Game Record!B2:B1000"), INDIRECT("Game Record!A2:A1000"), $A32, INDIRECT("Game Record!E2:E1000"), $C32) + SUMIFS(INDIRECT("Game Record!D2:D1000"), INDIRECT("Game Record!C2:C1000"), $A32, INDIRECT("Game Record!E2:E1000"), $C32)) / (COUNTIFS(INDIRECT("Game Record!A2:A1000"), $A32, INDIRECT("Game Record!E2:E1000"), $C32) + COUNTIFS(INDIRECT("Game Record!C2:C1000"), $A32, INDIRECT("Game Record!E2:E1000"), $C32)), 0) -> 0 | K32: =IFERROR(I32/(G32+H32))
D33: =IF(A33 = "", "", COUNTIFS('Game Record'!G:G, A33, 'Game Record'!E:E, C33)) | E33: =IF(A33 = "", "", COUNTIFS('Game Record'!H:H, A33, 'Game Record'!E:E, C33)) | F33: =SUMIFS(INDIRECT("Game Record!B2:B1000"), INDIRECT("Game Record!A2:A1000"), A33, INDIRECT("Game Record!E2:E1000"), C33) + SUMIFS(INDIRECT("Game Record!D2:D1000"), INDIRECT("Game Record!C2:C1000"), A33, INDIRECT("Game Record!E2:E1000"), C33) -> 0 | G33: =IF(A33 = "", "", COUNTIF('Game Record'!G:G, A33)) | H33: =IF(A33 = "", "", COUNTIF('Game Record'!H:H, A33)) | I33: =IFERROR(__xludf.DUMMYFUNCTION("SUM(FILTER(TeamARecordSet, INDEX(TeamARecordSet, 0, 1) = A33)) + SUM(FILTER(TeamBRecordSet, INDEX(TeamBRecordSet, 0, 1) = A33))"),0.0) -> 0 | J33: =IFERROR( (SUMIFS(INDIRECT("Game Record!B2:B1000"), INDIRECT("Game Record!A2:A1000"), $A33, INDIRECT("Game Record!E2:E1000"), $C33) + SUMIFS(INDIRECT("Game Record!D2:D1000"), INDIRECT("Game Record!C2:C1000"), $A33, INDIRECT("Game Record!E2:E1000"), $C33)) / (COUNTIFS(INDIRECT("Game Record!A2:A1000"), $A33, INDIRECT("Game Record!E2:E1000"), $C33) + COUNTIFS(INDIRECT("Game Record!C2:C1000"), $A33, INDIRECT("Game Record!E2:E1000"), $C33)), 0) -> 0 | K33: =IFERROR(I33/(G33+H33))
D34: =IF(A34 = "", "", COUNTIFS('Game Record'!G:G, A34, 'Game Record'!E:E, C34)) | E34: =IF(A34 = "", "", COUNTIFS('Game Record'!H:H, A34, 'Game Record'!E:E, C34)) | F34: =SUMIFS(INDIRECT("Game Record!B2:B1000"), INDIRECT("Game Record!A2:A1000"), A34, INDIRECT("Game Record!E2:E1000"), C34) + SUMIFS(INDIRECT("Game Record!D2:D1000"), INDIRECT("Game Record!C2:C1000"), A34, INDIRECT("Game Record!E2:E1000"), C34) -> 0 | G34: =IF(A34 = "", "", COUNTIF('Game Record'!G:G, A34)) | H34: =IF(A34 = "", "", COUNTIF('Game Record'!H:H, A34)) | I34: =IFERROR(__xludf.DUMMYFUNCTION("SUM(FILTER(TeamARecordSet, INDEX(TeamARecordSet, 0, 1) = A34)) + SUM(FILTER(TeamBRecordSet, INDEX(TeamBRecordSet, 0, 1) = A34))"),0.0) -> 0 | J34: =IFERROR( (SUMIFS(INDIRECT("Game Record!B2:B1000"), INDIRECT("Game Record!A2:A1000"), $A34, INDIRECT("Game Record!E2:E1000"), $C34) + SUMIFS(INDIRECT("Game Record!D2:D1000"), INDIRECT("Game Record!C2:C1000"), $A34, INDIRECT("Game Record!E2:E1000"), $C34)) / (COUNTIFS(INDIRECT("Game Record!A2:A1000"), $A34, INDIRECT("Game Record!E2:E1000"), $C34) + COUNTIFS(INDIRECT("Game Record!C2:C1000"), $A34, INDIRECT("Game Record!E2:E1000"), $C34)), 0) -> 0 | K34: =IFERROR(I34/(G34+H34))
D35: =IF(A35 = "", "", COUNTIFS('Game Record'!G:G, A35, 'Game Record'!E:E, C35)) | E35: =IF(A35 = "", "", COUNTIFS('Game Record'!H:H, A35, 'Game Record'!E:E, C35)) | F35: =SUMIFS(INDIRECT("Game Record!B2:B1000"), INDIRECT("Game Record!A2:A1000"), A35, INDIRECT("Game Record!E2:E1000"), C35) + SUMIFS(INDIRECT("Game Record!D2:D1000"), INDIRECT("Game Record!C2:C1000"), A35, INDIRECT("Game Record!E2:E1000"), C35) -> 0 | G35: =IF(A35 = "", "", COUNTIF('Game Record'!G:G, A35)) | H35: =IF(A35 = "", "", COUNTIF('Game Record'!H:H, A35)) | I35: =IFERROR(__xludf.DUMMYFUNCTION("SUM(FILTER(TeamARecordSet, INDEX(TeamARecordSet, 0, 1) = A35)) + SUM(FILTER(TeamBRecordSet, INDEX(TeamBRecordSet, 0, 1) = A35))"),0.0) -> 0 | J35: =IFERROR( (SUMIFS(INDIRECT("Game Record!B2:B1000"), INDIRECT("Game Record!A2:A1000"), $A35, INDIRECT("Game Record!E2:E1000"), $C35) + SUMIFS(INDIRECT("Game Record!D2:D1000"), INDIRECT("Game Record!C2:C1000"), $A35, INDIRECT("Game Record!E2:E1000"), $C35)) / (COUNTIFS(INDIRECT("Game Record!A2:A1000"), $A35, INDIRECT("Game Record!E2:E1000"), $C35) + COUNTIFS(INDIRECT("Game Record!C2:C1000"), $A35, INDIRECT("Game Record!E2:E1000"), $C35)), 0) -> 0 | K35: =IFERROR(I35/(G35+H35))
D36: =IF(A36 = "", "", COUNTIFS('Game Record'!G:G, A36, 'Game Record'!E:E, C36)) | E36: =IF(A36 = "", "", COUNTIFS('Game Record'!H:H, A36, 'Game Record'!E:E, C36)) | F36: =SUMIFS(INDIRECT("Game Record!B2:B1000"), INDIRECT("Game Record!A2:A1000"), A36, INDIRECT("Game Record!E2:E1000"), C36) + SUMIFS(INDIRECT("Game Record!D2:D1000"), INDIRECT("Game Record!C2:C1000"), A36, INDIRECT("Game Record!E2:E1000"), C36) -> 0 | G36: =IF(A36 = "", "", COUNTIF('Game Record'!G:G, A36)) | H36: =IF(A36 = "", "", COUNTIF('Game Record'!H:H, A36)) | I36: =IFERROR(__xludf.DUMMYFUNCTION("SUM(FILTER(TeamARecordSet, INDEX(TeamARecordSet, 0, 1) = A36)) + SUM(FILTER(TeamBRecordSet, INDEX(TeamBRecordSet, 0, 1) = A36))"),0.0) -> 0 | J36: =IFERROR( (SUMIFS(INDIRECT("Game Record!B2:B1000"), INDIRECT("Game Record!A2:A1000"), $A36, INDIRECT("Game Record!E2:E1000"), $C36) + SUMIFS(INDIRECT("Game Record!D2:D1000"), INDIRECT("Game Record!C2:C1000"), $A36, INDIRECT("Game Record!E2:E1000"), $C36)) / (COUNTIFS(INDIRECT("Game Record!A2:A1000"), $A36, INDIRECT("Game Record!E2:E1000"), $C36) + COUNTIFS(INDIRECT("Game Record!C2:C1000"), $A36, INDIRECT("Game Record!E2:E1000"), $C36)), 0) -> 0 | K36: =IFERROR(I36/(G36+H36))
D37: =IF(A37 = "", "", COUNTIFS('Game Record'!G:G, A37, 'Game Record'!E:E, C37)) | E37: =IF(A37 = "", "", COUNTIFS('Game Record'!H:H, A37, 'Game Record'!E:E, C37)) | F37: =SUMIFS(INDIRECT("Game Record!B2:B1000"), INDIRECT("Game Record!A2:A1000"), A37, INDIRECT("Game Record!E2:E1000"), C37) + SUMIFS(INDIRECT("Game Record!D2:D1000"), INDIRECT("Game Record!C2:C1000"), A37, INDIRECT("Game Record!E2:E1000"), C37) -> 0 | G37: =IF(A37 = "", "", COUNTIF('Game Record'!G:G, A37)) | H37: =IF(A37 = "", "", COUNTIF('Game Record'!H:H, A37)) | I37: =IFERROR(__xludf.DUMMYFUNCTION("SUM(FILTER(TeamARecordSet, INDEX(TeamARecordSet, 0, 1) = A37)) + SUM(FILTER(TeamBRecordSet, INDEX(TeamBRecordSet, 0, 1) = A37))"),0.0) -> 0 | J37: =IFERROR( (SUMIFS(INDIRECT("Game Record!B2:B1000"), INDIRECT("Game Record!A2:A1000"), $A37, INDIRECT("Game Record!E2:E1000"), $C37) + SUMIFS(INDIRECT("Game Record!D2:D1000"), INDIRECT("Game Record!C2:C1000"), $A37, INDIRECT("Game Record!E2:E1000"), $C37)) / (COUNTIFS(INDIRECT("Game Record!A2:A1000"), $A37, INDIRECT("Game Record!E2:E1000"), $C37) + COUNTIFS(INDIRECT("Game Record!C2:C1000"), $A37, INDIRECT("Game Record!E2:E1000"), $C37)), 0) -> 0 | K37: =IFERROR(I37/(G37+H37))
D38: =IF(A38 = "", "", COUNTIFS('Game Record'!G:G, A38, 'Game Record'!E:E, C38)) | E38: =IF(A38 = "", "", COUNTIFS('Game Record'!H:H, A38, 'Game Record'!E:E, C38)) | F38: =SUMIFS(INDIRECT("Game Record!B2:B1000"), INDIRECT("Game Record!A2:A1000"), A38, INDIRECT("Game Record!E2:E1000"), C38) + SUMIFS(INDIRECT("Game Record!D2:D1000"), INDIRECT("Game Record!C2:C1000"), A38, INDIRECT("Game Record!E2:E1000"), C38) -> 0 | G38: =IF(A38 = "", "", COUNTIF('Game Record'!G:G, A38)) | H38: =IF(A38 = "", "", COUNTIF('Game Record'!H:H, A38)) | I38: =IFERROR(__xludf.DUMMYFUNCTION("SUM(FILTER(TeamARecordSet, INDEX(TeamARecordSet, 0, 1) = A38)) + SUM(FILTER(TeamBRecordSet, INDEX(TeamBRecordSet, 0, 1) = A38))"),0.0) -> 0 | J38: =IFERROR( (SUMIFS(INDIRECT("Game Record!B2:B1000"), INDIRECT("Game Record!A2:A1000"), $A38, INDIRECT("Game Record!E2:E1000"), $C38) + SUMIFS(INDIRECT("Game Record!D2:D1000"), INDIRECT("Game Record!C2:C1000"), $A38, INDIRECT("Game Record!E2:E1000"), $C38)) / (COUNTIFS(INDIRECT("Game Record!A2:A1000"), $A38, INDIRECT("Game Record!E2:E1000"), $C38) + COUNTIFS(INDIRECT("Game Record!C2:C1000"), $A38, INDIRECT("Game Record!E2:E1000"), $C38)), 0) -> 0 | K38: =IFERROR(I38/(G38+H38))
D39: =IF(A39 = "", "", COUNTIFS('Game Record'!G:G, A39, 'Game Record'!E:E, C39)) | E39: =IF(A39 = "", "", COUNTIFS('Game Record'!H:H, A39, 'Game Record'!E:E, C39)) | F39: =SUMIFS(INDIRECT("Game Record!B2:B1000"), INDIRECT("Game Record!A2:A1000"), A39, INDIRECT("Game Record!E2:E1000"), C39) + SUMIFS(INDIRECT("Game Record!D2:D1000"), INDIRECT("Game Record!C2:C1000"), A39, INDIRECT("Game Record!E2:E1000"), C39) -> 0 | G39: =IF(A39 = "", "", COUNTIF('Game Record'!G:G, A39)) | H39: =IF(A39 = "", "", COUNTIF('Game Record'!H:H, A39)) | I39: =IFERROR(__xludf.DUMMYFUNCTION("SUM(FILTER(TeamARecordSet, INDEX(TeamARecordSet, 0, 1) = A39)) + SUM(FILTER(TeamBRecordSet, INDEX(TeamBRecordSet, 0, 1) = A39))"),0.0) -> 0 | J39: =IFERROR( (SUMIFS(INDIRECT("Game Record!B2:B1000"), INDIRECT("Game Record!A2:A1000"), $A39, INDIRECT("Game Record!E2:E1000"), $C39) + SUMIFS(INDIRECT("Game Record!D2:D1000"), INDIRECT("Game Record!C2:C1000"), $A39, INDIRECT("Game Record!E2:E1000"), $C39)) / (COUNTIFS(INDIRECT("Game Record!A2:A1000"), $A39, INDIRECT("Game Record!E2:E1000"), $C39) + COUNTIFS(INDIRECT("Game Record!C2:C1000"), $A39, INDIRECT("Game Record!E2:E1000"), $C39)), 0) -> 0 | K39: =IFERROR(I39/(G39+H39))
D40: =IF(A40 = "", "", COUNTIFS('Game Record'!G:G, A40, 'Game Record'!E:E, C40)) | E40: =IF(A40 = "", "", COUNTIFS('Game Record'!H:H, A40, 'Game Record'!E:E, C40)) | F40: =SUMIFS(INDIRECT("Game Record!B2:B1000"), INDIRECT("Game Record!A2:A1000"), A40, INDIRECT("Game Record!E2:E1000"), C40) + SUMIFS(INDIRECT("Game Record!D2:D1000"), INDIRECT("Game Record!C2:C1000"), A40, INDIRECT("Game Record!E2:E1000"), C40) -> 0 | G40: =IF(A40 = "", "", COUNTIF('Game Record'!G:G, A40)) | H40: =IF(A40 = "", "", COUNTIF('Game Record'!H:H, A40)) | I40: =IFERROR(__xludf.DUMMYFUNCTION("SUM(FILTER(TeamARecordSet, INDEX(TeamARecordSet, 0, 1) = A40)) + SUM(FILTER(TeamBRecordSet, INDEX(TeamBRecordSet, 0, 1) = A40))"),0.0) -> 0 | J40: =IFERROR( (SUMIFS(INDIRECT("Game Record!B2:B1000"), INDIRECT("Game Record!A2:A1000"), $A40, INDIRECT("Game Record!E2:E1000"), $C40) + SUMIFS(INDIRECT("Game Record!D2:D1000"), INDIRECT("Game Record!C2:C1000"), $A40, INDIRECT("Game Record!E2:E1000"), $C40)) / (COUNTIFS(INDIRECT("Game Record!A2:A1000"), $A40, INDIRECT("Game Record!E2:E1000"), $C40) + COUNTIFS(INDIRECT("Game Record!C2:C1000"), $A40, INDIRECT("Game Record!E2:E1000"), $C40)), 0) -> 0 | K40: =IFERROR(I40/(G40+H40))
...

Sheet Win Rates (Seasonal)
A1: 2021 | B1: Kadin | C1: Luke | D1: Griffin | E1: Ruben | F1: Mitch | G1: Jacob | H1: Andrew | I1: Connor | J1: Kyle | K1: Nick | L1: Raghav | M1: Michael
A2: Kadin | B2: =IF(A2=B$1, "", IF( (COUNTIFS(Winner, A2, Loser, B$1, Season, $A$1) + COUNTIFS(Winner, B$1, Loser, A2, Season, $A$1)) = 0, "", COUNTIFS(Winner, A2, Loser, B$1, Season, $A$1) / (COUNTIFS(Winner, A2, Loser, B$1, Season, $A$1) + COUNTIFS(Winner, B$1, Loser, A2, Season, $A$1)) ) ) | C2: =IF(A2=C$1, "", IF( (COUNTIFS(Winner, A2, Loser, C$1, Season, $A$1) + COUNTIFS(Winner, C$1, Loser, A2, Season, $A$1)) = 0, "", COUNTIFS(Winner, A2, Loser, C$1, Season, $A$1) / (COUNTIFS(Winner, A2, Loser, C$1, Season, $A$1) + COUNTIFS(Winner, C$1, Loser, A2, Season, $A$1)) ) ) -> 0.5 | D2: =IF(A2=D$1, "", IF( (COUNTIFS(Winner, A2, Loser, D$1, Season, $A$1) + COUNTIFS(Winner, D$1, Loser, A2, Season, $A$1)) = 0, "", COUNTIFS(Winner, A2, Loser, D$1, Season, $A$1) / (COUNTIFS(Winner, A2, Loser, D$1, Season, $A$1) + COUNTIFS(Winner, D$1, Loser, A2, Season, $A$1)) ) ) -> 0 | E2: =IF(A2=E$1, "", IF( (COUNTIFS(Winner, A2, Loser, E$1, Season, $A$1) + COUNTIFS(Winner, E$1, Loser, A2, Season, $A$1)) = 0, "", COUNTIFS(Winner, A2, Loser, E$1, Season, $A$1) / (COUNTIFS(Winner, A2, Loser, E$1, Season, $A$1) + COUNTIFS(Winner, E$1, Loser, A2, Season, $A$1)) ) ) -> 1 | F2: =IF(A2=F$1, "", IF( (COUNTIFS(Winner, A2, Loser, F$1, Season, $A$1) + COUNTIFS(Winner, F$1, Loser, A2, Season, $A$1)) = 0, "", COUNTIFS(Winner, A2, Loser, F$1, Season, $A$1) / (COUNTIFS(Winner, A2, Loser, F$1, Season, $A$1) + COUNTIFS(Winner, F$1, Loser, A2, Season, $A$1)) ) ) -> 0 | G2: =IF(A2=G$1, "", IF( (COUNTIFS(Winner, A2, Loser, G$1, Season, $A$1) + COUNTIFS(Winner, G$1, Loser, A2, Season, $A$1)) = 0, "", COUNTIFS(Winner, A2, Loser, G$1, Season, $A$1) / (COUNTIFS(Winner, A2, Loser, G$1, Season, $A$1) + COUNTIFS(Winner, G$1, Loser, A2, Season, $A$1)) ) ) -> 1 | H2: =IF(A2=H$1, "", IF( (COUNTIFS(Winner, A2, Loser, H$1, Season, $A$1) + COUNTIFS(Winner, H$1, Loser, A2, Season, $A$1)) = 0, "", COUNTIFS(Winner, A2, Loser, H$1, Season, $A$1) / (COUNTIFS(Winner, A2, Loser, H$1, Season, $A$1) + COUNTIFS(Winner, H$1, Loser, A2, Season, $A$1)) ) ) -> 1 | I2: =IF(A2=I$1, "", IF( (COUNTIFS(Winner, A2, Loser, I$1, Season, $A$1) + COUNTIFS(Winner, I$1, Loser, A2, Season, $A$1)) = 0, "", COUNTIFS(Winner, A2, Loser, I$1, Season, $A$1) / (COUNTIFS(Winner, A2, Loser, I$1, Season, $A$1) + COUNTIFS(Winner, I$1, Loser, A2, Season, $A$1)) ) ) -> 1 | J2: =IF(A2=J$1, "", IF( (COUNTIFS(Winner, A2, Loser, J$1, Season, $A$1) + COUNTIFS(Winner, J$1, Loser, A2, Season, $A$1)) = 0, "", COUNTIFS(Winner, A2, Loser, J$1, Season, $A$1) / (COUNTIFS(Winner, A2, Loser, J$1, Season, $A$1) + COUNTIFS(Winner, J$1, Loser, A2, Season, $A$1)) ) ) -> 0.5 | K2: =IF(A2=K$1, "", IF( (COUNTIFS(Winner, A2, Loser, K$1, Season, $A$1) + COUNTIFS(Winner, K$1, Loser, A2, Season, $A$1)) = 0, "", COUNTIFS(Winner, A2, Loser, K$1, Season, $A$1) / (COUNTIFS(Winner, A2, Loser, K$1, Season, $A$1) + COUNTIFS(Winner, K$1, Loser, A2, Season, $A$1)) ) ) -> 0.5 | L2: =IF(A2=L$1, "", IF( (COUNTIFS(Winner, A2, Loser, L$1, Season, $A$1) + COUNTIFS(Winner, L$1, Loser, A2, Season, $A$1)) = 0, "", COUNTIFS(Winner, A2, Loser, L$1, Season, $A$1) / (COUNTIFS(Winner, A2, Loser, L$1, Season, $A$1) + COUNTIFS(Winner, L$1, Loser, A2, Season, $A$1)) ) ) | M2: =IF(A2=M$1, "", IF( (COUNTIFS(Winner, A2, Loser, M$1, Season, $A$1) + COUNTIFS(Winner, M$1, Loser, A2, Season, $A$1)) = 0, "", COUNTIFS(Winner, A2, Loser, M$1, Season, $A$1) / (COUNTIFS(Winner, A2, Loser, M$1, Season, $A$1) + COUNTIFS(Winner, M$1, Loser, A2, Season, $A$1)) ) )
